Workbook
Name Slicer_Author: #N/A
Name Slicer_Genre: #N/A
Name Slicer_Year: #N/A

Sheet bestsellers with categories
A1: Name | B1: Author | C1: User Rating | D1: Reviews | E1: Price | F1: Year | G1: Genre
A2: 10-Day Green Smoothie Cleanse | B2: JJ Smith | C2: 4.7 | D2: 17350 | E2: 8 | F2: 2016 | G2: Non Fiction
A3: 11/22/63: A Novel | B3: Stephen King | C3: 4.6 | D3: 2052 | E3: 22 | F3: 2011 | G3: Fiction
A4: 12 Rules for Life: An Antidote to Chaos | B4: Jordan B. Peterson | C4: 4.7 | D4: 18979 | E4: 15 | F4: 2018 | G4: Non Fiction
A5: 1984 (Signet Classics) | B5: George Orwell | C5: 4.7 | D5: 21424 | E5: 6 | F5: 2017 | G5: Fiction
A6: 5,000 Awesome Facts (About Everything!) (National Geographic Kids) | B6: National Geographic Kids | C6: 4.8 | D6: 7665 | E6: 12 | F6: 2019 | G6: Non Fiction
A7: A Dance with Dragons (A Song of Ice and Fire) | B7: George R. R. Martin | C7: 4.4 | D7: 12643 | E7: 11 | F7: 2011 | G7: Fiction
A8: A Game of Thrones / A Clash of Kings / A Storm of Swords / A Feast of Crows / A Dance with Dragons | B8: George R. R. Martin | C8: 4.7 | D8: 19735 | E8: 30 | F8: 2014 | G8: Fiction
A9: A Gentleman in Moscow: A Novel | B9: Amor Towles | C9: 4.7 | D9: 19699 | E9: 15 | F9: 2017 | G9: Fiction
A10: A Higher Loyalty: Truth, Lies, and Leadership | B10: James Comey | C10: 4.7 | D10: 5983 | E10: 3 | F10: 2018 | G10: Non Fiction
A11: A Man Called Ove: A Novel | B11: Fredrik Backman | C11: 4.6 | D11: 23848 | E11: 8 | F11: 2016 | G11: Fiction
A12: A Man Called Ove: A Novel | B12: Fredrik Backman | C12: 4.6 | D12: 23848 | E12: 8 | F12: 2017 | G12: Fiction
A13: A Patriot's History of the United States: From Columbus's Great Discovery to the War on Terror | B13: Larry Schweikart | C13: 4.6 | D13: 460 | E13: 2 | F13: 2010 | G13: Non Fiction
... A551: You Are a Badass: How to Stop Doubting Your Greatness and Start Living an Awesome Life | B551: Jen Sincero | C551: 4.7 | D551: 14331 | E551: 8 | F551: 2019 | G551: Non Fiction

Sheet Data Cleaning
A1: Name | B1: Author | C1: User Rating | D1: Reviews | E1: Price | F1: Year | G1: Genre | M1: author | O1: reviews
A2: 10-Day Green Smoothie Cleanse | B2: JJ Smith | C2: 4.7 | D2: 17350 | E2: 8 | F2: 2016 | G2: Non Fiction | M2: JJ Smith | O2: =SUMIF(B:B,M2,D:D) -> 17350 | P2: =_xlfn.XLOOKUP(MAX(O2:O249),O2:O249,M2:M249) -> Suzanne Collins | Q2: =MAX(O2:O249) -> 278329
A3: 11/22/63: A Novel | B3: Stephen King | C3: 4.6 | D3: 2052 | E3: 22 | F3: 2011 | G3: Fiction | M3: Stephen King | O3: =SUMIF(B:B,M3,D:D) -> 29385 | P3: =_xlfn.XLOOKUP(MIN(O2:O249),O2:O249,M2:M249) -> Zhi Gang Sha | Q3: =MIN(O2:O249) -> 257
A4: 12 Rules for Life: An Antidote to Chaos | B4: Jordan B. Peterson | C4: 4.7 | D4: 18979 | E4: 15 | F4: 2018 | G4: Non Fiction | M4: Jordan B. Peterson | O4: =SUMIF(B:B,M4,D:D) -> 18979
A5: 1984 (Signet Classics) | B5: George Orwell | C5: 4.7 | D5: 21424 | E5: 6 | F5: 2017 | G5: Fiction | M5: George Orwell | O5: =SUMIF(B:B,M5,D:D) -> 21424
A6: 5,000 Awesome Facts (About Everything!) (National Geographic Kids) | B6: National Geographic Kids | C6: 4.8 | D6: 7665 | E6: 12 | F6: 2019 | G6: Non Fiction | M6: National Geographic Kids | O6: =SUMIF(B:B,M6,D:D) -> 7665
A7: A Dance with Dragons (A Song of Ice and Fire) | B7: George R. R. Martin | C7: 4.4 | D7: 12643 | E7: 11 | F7: 2011 | G7: Fiction | M7: George R. R. Martin | O7: =SUMIF(B:B,M7,D:D) -> 32378
A8: A Game of Thrones / A Clash of Kings / A Storm of Swords / A Feast of Crows / A Dance with Dragons | B8: George R. R. Martin | C8: 4.7 | D8: 19735 | E8: 30 | F8: 2014 | G8: Fiction | M8: Amor Towles | O8: =SUMIF(B:B,M8,D:D) -> 19699
A9: A Gentleman in Moscow: A Novel | B9: Amor Towles | C9: 4.7 | D9: 19699 | E9: 15 | F9: 2017 | G9: Fiction | M9: James Comey | O9: =SUMIF(B:B,M9,D:D) -> 5983
A10: A Higher Loyalty: Truth, Lies, and Leadership | B10: James Comey | C10: 4.7 | D10: 5983 | E10: 3 | F10: 2018 | G10: Non Fiction | M10: Fredrik Backman | O10: =SUMIF(B:B,M10,D:D) -> 47696
A11: A Man Called Ove: A Novel | B11: Fredrik Backman | C11: 4.6 | D11: 23848 | E11: 8 | F11: 2016 | G11: Fiction | M11: Larry Schweikart | O11: =SUMIF(B:B,M11,D:D) -> 460
A12: A Man Called Ove: A Novel | B12: Fredrik Backman | C12: 4.6 | D12: 23848 | E12: 8 | F12: 2017 | G12: Fiction | M12: Jaycee Dugard | O12: =SUMIF(B:B,M12,D:D) -> 4149
A13: A Patriot's History of the United States: From Columbus's Great Discovery to the War on Terror | B13: Larry Schweikart | C13: 4.6 | D13: 460 | E13: 2 | F13: 2010 | G13: Non Fiction | M13: Madeleine L'Engle | O13: =SUMIF(B:B,M13,D:D) -> 5153
A14: A Stolen Life: A Memoir | B14: Jaycee Dugard | C14: 4.6 | D14: 4149 | E14: 32 | F14: 2011 | G14: Non Fiction | M14: Steve Harvey | O14: =SUMIF(B:B,M14,D:D) -> 5013
A15: A Wrinkle in Time (Time Quintet) | B15: Madeleine L'Engle | C15: 4.5 | D15: 5153 | E15: 5 | F15: 2018 | G15: Fiction | M15: Adult Coloring Book Designs | O15: =SUMIF(B:B,M15,D:D) -> 2313
... A37: Between the World and Me | B37: Ta-Nehisi Coates | C37: 4.7 | D37: 10070 | E37: 13 | F37: 2015 | G37: Non Fiction | M37: David Goggins | O37: =SUMIF(B:B,M37,D:D) -> 16244
A38: Between the World and Me | B38: Ta-Nehisi Coates | C38: 4.7 | D38: 10070 | E38: 13 | F38: 2016 | G38: Non Fiction | I38: {=I2s} -> #NAME? | M38: Thomas Piketty | O38: =SUMIF(B:B,M38,D:D) -> 2884
A39: Born to Run | B39: Bruce Springsteen | C39: 4.7 | D39: 3729 | E39: 18 | F39: 2016 | G39: Non Fiction | M39: Suzanne Collins | O39: =SUMIF(B:B,M39,D:D) -> 278329
A40: Breaking Dawn (The Twilight Saga, Book 4) | B40: Stephenie Meyer | C40: 4.6 | D40: 9769 | E40: 13 | F40: 2009 | G40: Fiction | M40: Chrissy Teigen | O40: =SUMIF(B:B,M40,D:D) -> 4761
A41: Broke: The Plan to Restore Our Trust, Truth and Treasure | B41: Glenn Beck | C41: 4.5 | D41: 471 | E41: 8 | F41: 2010 | G41: Non Fiction | M41: Francis Chan | O41: =SUMIF(B:B,M41,D:D) -> 4626
A42: Brown Bear, Brown Bear, What Do You See? | B42: Bill Martin Jr. | C42: 4.9 | D42: 14344 | E42: 5 | F42: 2017 | G42: Fiction | M42: Kevin Kwan | O42: =SUMIF(B:B,M42,D:D) -> 6143
A43: Brown Bear, Brown Bear, What Do You See? | B43: Bill Martin Jr. | C43: 4.9 | D43: 14344 | E43: 5 | F43: 2019 | G43: Fiction | M43: Marjorie Sarnat | O43: =SUMIF(B:B,M43,D:D) -> 7893
A44: Cabin Fever (Diary of a Wimpy Kid, Book 6) | B44: Jeff Kinney | C44: 4.8 | D44: 4505 | E44: 11 | F44: 2011 | G44: Fiction | M44: Abraham Verghese | O44: =SUMIF(B:B,M44,D:D) -> 9732
A45: Calm the F*ck Down: An Irreverent Adult Coloring Book (Irreverent Book Series) | B45: Sasha O'Hara | C45: 4.6 | D45: 10369 | E45: 4 | F45: 2016 | G45: Non Fiction | M45: BreneÌ Brown | O45: =SUMIF(B:B,M45,D:D) -> 1329
A46: Can't Hurt Me: Master Your Mind and Defy the Odds | B46: David Goggins | C46: 4.8 | D46: 16244 | E46: 18 | F46: 2019 | G46: Non Fiction | M46: Malcolm Gladwell | O46: =SUMIF(B:B,M46,D:D) -> 28997
A47: Capital in the Twenty First Century | B47: Thomas Piketty | C47: 4.5 | D47: 2884 | E47: 28 | F47: 2014 | G47: Non Fiction | M47: Charlaine Harris | O47: =SUMIF(B:B,M47,D:D) -> 6532
A48: Catching Fire (The Hunger Games) | B48: Suzanne Collins | C48: 4.7 | D48: 22614 | E48: 11 | F48: 2010 | G48: Fiction | M48: Rod Campbell | O48: =SUMIF(B:B,M48,D:D) -> 43688
A49: Catching Fire (The Hunger Games) | B49: Suzanne Collins | C49: 4.7 | D49: 22614 | E49: 11 | F49: 2011 | G49: Fiction | M49: George W. Bush | O49: =SUMIF(B:B,M49,D:D) -> 2137
A50: Catching Fire (The Hunger Games) | B50: Suzanne Collins | C50: 4.7 | D50: 22614 | E50: 11 | F50: 2012 | G50: Fiction | M50: Tony Hsieh | O50: =SUMIF(B:B,M50,D:D) -> 1651
... A249: Oh, the Places You'll Go! | B249: Dr. Seuss | C249: 4.9 | D249: 21834 | E249: 8 | F249: 2014 | G249: Fiction | M249: Jen Sincero | O249: =SUMIF(B:B,M249,D:D) -> 57324
A250: Oh, the Places You'll Go! | B250: Dr. Seuss | C250: 4.9 | D250: 21834 | E250: 8 | F250: 2015 | G250: Fiction
A251: Oh, the Places You'll Go! | B251: Dr. Seuss | C251: 4.9 | D251: 21834 | E251: 8 | F251: 2016 | G251: Fiction
A252: Oh, the Places You'll Go! | B252: Dr. Seuss | C252: 4.9 | D252: 21834 | E252: 8 | F252: 2017 | G252: Fiction
A253: Oh, the Places You'll Go! | B253: Dr. Seuss | C253: 4.9 | D253: 21834 | E253: 8 | F253: 2018 | G253: Fiction
A254: Oh, the Places You'll Go! | B254: Dr. Seuss | C254: 4.9 | D254: 21834 | E254: 8 | F254: 2019 | G254: Fiction
A255: Old School (Diary of a Wimpy Kid #10) | B255: Jeff Kinney | C255: 4.8 | D255: 6169 | E255: 7 | F255: 2015 | G255: Fiction
A256: Olive Kitteridge | B256: Elizabeth Strout | C256: 4.2 | D256: 4519 | E256: 12 | F256: 2009 | G256: Fiction
A257: One Thousand Gifts: A Dare to Live Fully Right Where You Are | B257: Ann Voskamp | C257: 4.6 | D257: 3163 | E257: 13 | F257: 2011 | G257: Non Fiction
A258: One Thousand Gifts: A Dare to Live Fully Right Where You Are | B258: Ann Voskamp | C258: 4.6 | D258: 3163 | E258: 13 | F258: 2012 | G258: Non Fiction
A259: Option B: Facing Adversity, Building Resilience, and Finding Joy | B259: Sheryl Sandberg | C259: 4.5 | D259: 1831 | E259: 9 | F259: 2017 | G259: Non Fiction
...

Sheet Answers
A1: Steps to analyze data for best sellers categories
A7: Data Cleaning
A11: Step | B11: Description | C11: Status | D11: Notes
A12: 1 | B12: I made a sheet and called it 'data cleaning' and added a copy of best sellers with categories | C12: Done | D12: _____ | G12: Exploratory Data Analysis
A13: =A12+1 -> 2 | B13: I collected the data in a table and named it 'Books'. | C13: Done | D13: ______
A14: =A13+1 -> 3 | B14: I searched for blank cells and no empty cells were found. | C14: Done | D14: ______ | I14: step | J14: The requirement | K14: Answers
A15: =A14+1 -> 4 | B15: I searched for duplicate values. Two duplicate values ​​were found. They were removed and one value was left for each. | C15: Done | D15: ______ | I15: 1 | J15: Total Price | K15: =SUM(Books[Price]) -> 7281
A16: =A15+1 -> 5 | B16: 12 books with zero prices were found and dealt with by searching for their prices and adding them | C16: Done | D16: ______ | I16: =I15+1 -> 2 | J16: Average Price | K16: =AVERAGE(Books[Price]) -> 13.286496 | S16: Data Visualization
A17: =A16+1 -> 6 | B17: Column formatting has been verified. | C17: Done | D17: ______ | I17: =I16+1 -> 3 | J17: Maximum Price | K17: =MAX(Books[Price]) -> 105
I18: =I17+1 -> 4 | J18: Minimum Price | K18: =MIN(Books[Price]) -> 1 | S18: Step | T18: Description | U18: Statue | V18: Notes
I19: =I18+1 -> 5 | J19: Average User Rating | K19: =AVERAGE(Books[User Rating]) -> 4.6178832 | S19: 1 | T19: A sheet called data visualization was created. | U19: Done | V19: _______
I20: =I19+1 -> 6 | J20: Total Reviews | K20: =SUM('Data Cleaning'!D:D) -> 6494150 | S20: =1+S19 -> 2 | T20: A dash board was created containing graphics with impactful data. | U20: Done | V20: _______
I21: =I20+1 -> 7 | J21: Average Reviews | K21: =AVERAGE(Books[[#All],[Reviews]]) -> 11850.639 | S21: =1+S20 -> 3 | T21: A column chart was created to create a relationship between the average price and the average rating for each year. | U21: Done | V21: _______
I22: =I21+1 -> 8 | J22: Num of fiction books | K22: =COUNTIF(Books[Genre],'Data Cleaning'!G540) -> 239 | S22: =1+S21 -> 4 | T22: A pie chart was created to establish a relationship between the total reviews for each year. | U22: Done | V22: _______
I23: =I22+1 -> 9 | J23: Num of non-fiction books | K23: =COUNTIF(Books[Genre],'Data Cleaning'!G539) -> 309 | S23: =1+S22 -> 5 | T23: A bar chart was created to create a relationship between the total reviews and the average rating for each author. | U23: Done | V23: _______
I24: =I23+1 -> 10 | J24: The most commented book | K24: =_xlfn.CONCAT(_xlfn.XLOOKUP(MAX('Data Cleaning'!D:D),'Data Cleaning'!D:D,'Data Cleaning'!A:A)," Got 88 k comments ") -> Where the Crawdads Sing Got 88 k comments | S24: =1+S23 -> 6 | T24: A column chart was created to create a relationship between the total reviews for each year. | U24: Done | V24: _______
I25: =I24+1 -> 11 | J25: The least commented book | K25: =_xlfn.CONCAT(_xlfn.XLOOKUP(MIN('Data Cleaning'!D:D),'Data Cleaning'!D:D,'Data Cleaning'!A:A)," Got 36 comments ") -> Divine Soul Mind Body Healing and Transmission System: The Divine Way to Heal You, Humanity, Mother Earth, and Allâ€¦ Got 36 comments | S25: =1+S24 -> 7 | T25: A slicer was created for each chart and they were all linked together. | U25: Done | V25: _______
I26: =I25+1 -> 12 | J26: Number of reviews for a fiction books | K26: =SUMIF('Data Cleaning'!G:G,'Data Cleaning'!G3,'Data Cleaning'!D:D) -> 3713628
I27: =I26+1 -> 13 | J27: Number of reviews for a non fiction books | K27: =SUMIF('Data Cleaning'!G:G,'Data Cleaning'!G2,'Data Cleaning'!D:D) -> 2780522
I28: =I27+1 -> 14 | J28: The author with the most reviews | K28: =_xlfn.CONCAT('Data Cleaning'!P2," has ",'Data Cleaning'!Q2) -> Suzanne Collins has 278329
I29: =I28+1 -> 15 | J29: The author with the fewest reviews | K29: =_xlfn.CONCAT('Data Cleaning'!P3," has ",'Data Cleaning'!Q3) -> Zhi Gang Sha has 257
I30: A sheet containing relationships between columns was created and named exploratory data analysis.

Sheet Relation 1
B6: Year | C6: Average of User Rating | D6: Average of Price
B7: 2011 | C7: 4.558 | D7: 15.32
B8: 2012 | C8: 4.532 | D8: 15.3
B9: 2013 | C9: 4.554 | D9: 14.94
B10: 2014 | C10: 4.6166667 | D10: 15.333333
B11: 2019 | C11: 4.74 | D11: 10.08
B12: 2010 | C12: 4.558 | D12: 13.68
B13: 2009 | C13: 4.584 | D13: 15.4
B14: 2015 | C14: 4.648 | D14: 10.56
B15: 2016 | C15: 4.678 | D15: 13.46
B16: 2017 | C16: 4.66 | D16: 11.64
B17: 2018 | C17: 4.668 | D17: 10.52
B18: Grand Total | C18: 4.6178832 | D18: 13.286496

Sheet Relation 2,3
B11: Genre | C11: Average of User Rating | L11: Genre | M11: Sum of Reviews
B12: Fiction | C12: 4.6481172 | L12: Fiction | M12: 3713628
B13: Non Fiction | C13: 4.5944984 | L13: Non Fiction | M13: 2780522
B14: Grand Total | C14: 4.6178832 | L14: Grand Total | M14: 6494150

Sheet Relation 4
B6: Genre
B7: Fiction | D7: Non Fiction | F7: Total Sum of Reviews | G7: Total Average of Price
A8: Year | B8: Sum of Reviews | C8: Average of Price | D8: Sum of Reviews | E8: Average of Price
A9: 2009 | B9: 156824 | C9: 15.583333 | D9: 78682 | E9: 15.230769 | F9: 235506 | G9: 15.4
A10: 2010 | B10: 168185 | C10: 10.2 | D10: 105796 | E10: 16 | F10: 273981 | G10: 13.68
A11: 2011 | B11: 217041 | C11: 12.142857 | D11: 188000 | E11: 17.62069 | F11: 405041 | G11: 15.32
A12: 2012 | B12: 417821 | C12: 12.285714 | D12: 236725 | E12: 17.482759 | F12: 654546 | G12: 15.3
A13: 2013 | B13: 479684 | C13: 11.416667 | D13: 175223 | E13: 18.192308 | F13: 654907 | G13: 14.94
A14: 2014 | B14: 511621 | C14: 11.214286 | D14: 201221 | E14: 21.1 | F14: 712842 | G14: 15.333333
A15: 2015 | B15: 403004 | C15: 9.7647059 | D15: 308665 | E15: 10.969697 | F15: 711669 | G15: 10.56
A16: 2016 | B16: 371702 | C16: 13 | D16: 338098 | E16: 13.741935 | F16: 709800 | G16: 13.46
A17: 2017 | B17: 350684 | C17: 9.375 | D17: 293736 | E17: 13.730769 | F17: 644420 | G17: 11.64
A18: 2018 | B18: 266919 | C18: 8.7619048 | D18: 429602 | E18: 11.793103 | F18: 696521 | G18: 10.52
A19: 2019 | B19: 370143 | C19: 9.35 | D19: 424774 | E19: 10.566667 | F19: 794917 | G19: 10.08
A20: Grand Total | B20: 3713628 | C20: 11.246862 | D20: 2780522 | E20: 14.864078 | F20: 6494150 | G20: 13.286496

Sheet Relation 5,6
B6: Year | C6: Sum of Reviews
B7: 2009 | C7: 235506
B8: 2010 | C8: 273981
B9: 2011 | C9: 405041
B10: 2012 | C10: 654546
B11: 2013 | C11: 654907
B12: 2014 | C12: 712842
B13: 2015 | C13: 711669
B14: 2016 | C14: 709800
B15: 2017 | C15: 644420
B16: 2018 | C16: 696521
B17: 2019 | C17: 794917
B18: Grand Total | C18: 6494150
B29: Author | C29: Sum of Reviews | D29: Average of User Rating
B30: Suzanne Collins | C30: 278329 | D30: 4.6636364
B31: E L James | C31: 178011 | D31: 4.2333333
B32: Dr. Seuss | C32: 176545 | D32: 4.8777778
B33: Gillian Flynn | C33: 171813 | D33: 4
B34: John Green | C34: 159937 | D34: 4.65
B35: Paula Hawkins | C35: 158892 | D35: 4.1
B36: Harper Lee | C36: 146152 | D36: 4.6
B37: Gary Chapman | C37: 145958 | D37: 4.7363636
B38: Don Miguel Ruiz | C38: 139848 | D38: 4.7
B39: Eric Carle | C39: 136822 | D39: 4.9
B40: Grand Total | C40: 1692307 | D40: 4.64

Sheet Relation 7
A7: Book Name | B7: Sum of Reviews | C7: Average of User Rating
A8: Oh, the Places You'll Go!
A9: Fiction | B9: 174672 | C9: 4.9
A10: Gone Girl
A11: Fiction | B11: 171813 | C11: 4
A12: The Girl on the Train
A13: Fiction | B13: 158892 | C13: 4.1
A14: The Fault in Our Stars
A15: Fiction | B15: 151446 | C15: 4.7
A16: The 5 Love Languages: The Secret to Love That Lasts
A17: Non Fiction | B17: 145155 | C17: 4.75
A18: The Four Agreements: A Practical Guide to Personal Freedom (A Toltec Wisdom Book)
A19: Non Fiction | B19: 139848 | C19: 4.7
A20: The Very Hungry Caterpillar
A21: Fiction | B21: 136822 | C21: 4.9
A22: To Kill a Mockingbird
A23: Fiction | B23: 131170 | C23: 4.8
A24: How to Win Friends & Influence People
A25: Non Fiction | B25: 125005 | C25: 4.7
A26: Becoming
A27: Non Fiction | B27: 122266 | C27: 4.8
A28: Grand Total | B28: 1457089 | C28: 4.7176471

Sheet Data Visualization

Sheet Insights
